#include <iostream>
#include <stdexcept>

int main() {
    try {
        int numerator = 10;
        int denominator = 0;
        int result = numerator / denominator;
        std::cout << "Result: " << result << std::endl;
    } catch (const std::logic_error& e) {
        std::cout << "A logic_error occurred: " << e.what() << std::endl;
    } catch (const std::exception& e) {
        std::cout << "An exception occurred: " << e.what() << std::endl;
    }
    std::cout << "Program continues after the exception handling." << std::endl;

    return 0;
}
